<?xml version="1.0" ?>
<robot name="turtlebot3_moguarder" xmlns:xacro="http://ros.org/wiki/xacro">
  <xacro:include filename="$(find turtlebot3_description)/urdf_next/common_properties.xacro"/>
  <xacro:include filename="$(find turtlebot3_description)/urdf_next/turtlebot3_moguarder.gazebo.xacro"/>

  <link name="base_footprint"/>

  <joint name="base_joint" type="fixed">
    <parent link="base_footprint"/>
    <child link="base_link"/>
    <origin xyz="0.0 0.0 0.010" rpy="0 0 0"/>
  </joint>

  <link name="base_link">
    <collision>
      <origin xyz="-0.020 0 0.050" rpy="0 0 0"/>
      <geometry>
        <box size="0.135 0.130 0.105"/>
      </geometry>
    </collision>

    <inertial>
      <origin xyz="-0.010 0 0.035" rpy="0 0 0"/>
      <mass value="8.2573504e-01"/>
      <inertia ixx="1.8500000e-03" ixy="0.0" ixz="0.0"
               iyy="1.9000000e-03" iyz="0.0"
               izz="1.9500000e-03" />
    </inertial>
  </link>

  <joint name="center_body_joint" type="fixed">
    <parent link="base_link"/>
    <child link="center_body_link"/>
    <origin xyz="-0.015 0 0.045" rpy="0 0 0"/>
  </joint>

  <link name="center_body_link">
    <visual>
      <origin xyz="0 0 0" rpy="0 0 0"/>
      <geometry>
        <box size="0.115 0.125 0.060"/>
      </geometry>
      <material name="charcoal"/>
    </visual>

    <collision>
      <origin xyz="0 0 0" rpy="0 0 0"/>
      <geometry>
        <box size="0.115 0.125 0.060"/>
      </geometry>
    </collision>

    <inertial>
      <origin xyz="0 0 0" />
      <mass value="0.180" />
      <inertia ixx="1.3e-04" ixy="0.0" ixz="0.0"
               iyy="1.4e-04" iyz="0.0"
               izz="1.6e-04" />
    </inertial>
  </link>

  <joint name="front_shell_joint" type="fixed">
    <parent link="base_link"/>
    <child link="front_shell_link"/>
    <origin xyz="0.060 0 0.038" rpy="0 0 0"/>
  </joint>

  <link name="front_shell_link">
    <visual>
      <origin xyz="0 0 0" rpy="0 0 0"/>
      <geometry>
        <box size="0.075 0.115 0.042"/>
      </geometry>
      <material name="charcoal"/>
    </visual>

    <collision>
      <origin xyz="0 0 0" rpy="0 0 0"/>
      <geometry>
        <box size="0.075 0.115 0.042"/>
      </geometry>
    </collision>

    <inertial>
      <origin xyz="0 0 0" />
      <mass value="0.080" />
      <inertia ixx="8.0e-05" ixy="0.0" ixz="0.0"
               iyy="8.0e-05" iyz="0.0"
               izz="1.0e-04" />
    </inertial>
  </link>

  <joint name="rear_module_joint" type="fixed">
    <parent link="base_link"/>
    <child link="rear_module_link"/>
    <origin xyz="-0.073 0 0.070" rpy="0 0 0"/>
  </joint>

  <link name="rear_module_link">
    <visual>
      <origin xyz="0 0 0" rpy="0 0 0"/>
      <geometry>
        <box size="0.050 0.105 0.060"/>
      </geometry>
      <material name="matte_black"/>
    </visual>

    <collision>
      <origin xyz="0 0 0" rpy="0 0 0"/>
      <geometry>
        <box size="0.050 0.105 0.060"/>
      </geometry>
    </collision>

    <inertial>
      <origin xyz="0 0 0" />
      <mass value="0.090" />
      <inertia ixx="7.0e-05" ixy="0.0" ixz="0.0"
               iyy="7.5e-05" iyz="0.0"
               izz="9.0e-05" />
    </inertial>
  </link>

  <joint name="front_bumper_joint" type="fixed">
    <parent link="base_link"/>
    <child link="front_bumper_link"/>
    <origin xyz="0.105 0 0.030" rpy="0 0 0"/>
  </joint>

  <link name="front_bumper_link">
    <visual>
      <origin xyz="0 0 0" rpy="0 0 0"/>
      <geometry>
        <box size="0.030 0.155 0.028"/>
      </geometry>
      <material name="matte_black"/>
    </visual>

    <collision>
      <origin xyz="0 0 0" rpy="0 0 0"/>
      <geometry>
        <box size="0.030 0.155 0.028"/>
      </geometry>
    </collision>

    <inertial>
      <origin xyz="0 0 0" />
      <mass value="0.045" />
      <inertia ixx="2.0e-05" ixy="0.0" ixz="0.0"
               iyy="2.5e-05" iyz="0.0"
               izz="3.0e-05" />
    </inertial>
  </link>

  <joint name="left_side_plate_joint" type="fixed">
    <parent link="base_link"/>
    <child link="left_side_plate_link"/>
    <origin xyz="-0.015 0.077 0.042" rpy="0 0 0"/>
  </joint>

  <link name="left_side_plate_link">
    <visual>
      <origin xyz="0 0 0" rpy="0 0 0"/>
      <geometry>
        <box size="0.145 0.014 0.040"/>
      </geometry>
      <material name="matte_black"/>
    </visual>

    <collision>
      <origin xyz="0 0 0" rpy="0 0 0"/>
      <geometry>
        <box size="0.145 0.014 0.040"/>
      </geometry>
    </collision>

    <inertial>
      <origin xyz="0 0 0" />
      <mass value="0.035" />
      <inertia ixx="1.5e-05" ixy="0.0" ixz="0.0"
               iyy="1.5e-05" iyz="0.0"
               izz="2.0e-05" />
    </inertial>
  </link>

  <joint name="right_side_plate_joint" type="fixed">
    <parent link="base_link"/>
    <child link="right_side_plate_link"/>
    <origin xyz="-0.015 -0.077 0.042" rpy="0 0 0"/>
  </joint>

  <link name="right_side_plate_link">
    <visual>
      <origin xyz="0 0 0" rpy="0 0 0"/>
      <geometry>
        <box size="0.145 0.014 0.040"/>
      </geometry>
      <material name="dark"/>
    </visual>

    <collision>
      <origin xyz="0 0 0" rpy="0 0 0"/>
      <geometry>
        <box size="0.145 0.014 0.040"/>
      </geometry>
    </collision>

    <inertial>
      <origin xyz="0 0 0" />
      <mass value="0.035" />
      <inertia ixx="1.5e-05" ixy="0.0" ixz="0.0"
               iyy="1.5e-05" iyz="0.0"
               izz="2.0e-05" />
    </inertial>
  </link>

  <joint name="lidar_mount_joint" type="fixed">
    <parent link="base_link"/>
    <child link="lidar_mount_link"/>
    <origin xyz="0.035 0 0.052" rpy="0 0 0"/>
  </joint>

  <link name="lidar_mount_link">
    <visual>
      <origin xyz="0 0 0" rpy="0 0 0"/>
      <geometry>
        <box size="0.060 0.072 0.014"/>
      </geometry>
      <material name="dark"/>
    </visual>

    <collision>
      <origin xyz="0 0 0" rpy="0 0 0"/>
      <geometry>
        <box size="0.060 0.072 0.014"/>
      </geometry>
    </collision>

    <inertial>
      <origin xyz="0 0 0" />
      <mass value="0.025" />
      <inertia ixx="1.0e-05" ixy="0.0" ixz="0.0"
               iyy="1.0e-05" iyz="0.0"
               izz="1.2e-05" />
    </inertial>
  </link>

  <joint name="lidar_guard_left_joint" type="fixed">
    <parent link="base_link"/>
    <child link="lidar_guard_left_link"/>
    <origin xyz="0.035 0.044 0.086" rpy="0 0 0"/>
  </joint>

  <link name="lidar_guard_left_link">
    <visual>
      <origin xyz="0 0 0" rpy="0 0 0"/>
      <geometry>
        <box size="0.070 0.010 0.050"/>
      </geometry>
      <material name="matte_black"/>
    </visual>

    <collision>
      <origin xyz="0 0 0" rpy="0 0 0"/>
      <geometry>
        <box size="0.070 0.010 0.050"/>
      </geometry>
    </collision>

    <inertial>
      <origin xyz="0 0 0" />
      <mass value="0.018" />
      <inertia ixx="8.0e-06" ixy="0.0" ixz="0.0"
               iyy="8.0e-06" iyz="0.0"
               izz="9.0e-06" />
    </inertial>
  </link>

  <joint name="lidar_guard_right_joint" type="fixed">
    <parent link="base_link"/>
    <child link="lidar_guard_right_link"/>
    <origin xyz="0.035 -0.044 0.086" rpy="0 0 0"/>
  </joint>

  <link name="lidar_guard_right_link">
    <visual>
      <origin xyz="0 0 0" rpy="0 0 0"/>
      <geometry>
        <box size="0.070 0.010 0.050"/>
      </geometry>
      <material name="matte_black"/>
    </visual>

    <collision>
      <origin xyz="0 0 0" rpy="0 0 0"/>
      <geometry>
        <box size="0.070 0.010 0.050"/>
      </geometry>
    </collision>

    <inertial>
      <origin xyz="0 0 0" />
      <mass value="0.018" />
      <inertia ixx="8.0e-06" ixy="0.0" ixz="0.0"
               iyy="8.0e-06" iyz="0.0"
               izz="9.0e-06" />
    </inertial>
  </link>

  <joint name="top_comm_module_joint" type="fixed">
    <parent link="base_link"/>
    <child link="top_comm_module_link"/>
    <origin xyz="-0.030 0 0.115" rpy="0 0 0"/>
  </joint>

  <link name="top_comm_module_link">
    <visual>
      <origin xyz="0 0 0" rpy="0 0 0"/>
      <geometry>
        <box size="0.060 0.060 0.026"/>
      </geometry>
      <material name="charcoal"/>
    </visual>

    <collision>
      <origin xyz="0 0 0" rpy="0 0 0"/>
      <geometry>
        <box size="0.060 0.060 0.026"/>
      </geometry>
    </collision>

    <inertial>
      <origin xyz="0 0 0" />
      <mass value="0.040" />
      <inertia ixx="1.4e-05" ixy="0.0" ixz="0.0"
               iyy="1.4e-05" iyz="0.0"
               izz="1.8e-05" />
    </inertial>
  </link>

  <joint name="left_range_joint" type="fixed">
    <parent link="base_link"/>
    <child link="left_range_link"/>
    <origin xyz="0.020 0.090 0.055" rpy="0 0 1.5708"/>
  </joint>

  <link name="left_range_link">
    <visual>
      <origin xyz="0 0 0" rpy="0 0 0"/>
      <geometry>
        <box size="0.026 0.018 0.020"/>
      </geometry>
      <material name="sensor_glass"/>
    </visual>

    <collision>
      <origin xyz="0 0 0" rpy="0 0 0"/>
      <geometry>
        <box size="0.026 0.018 0.020"/>
      </geometry>
    </collision>

    <inertial>
      <origin xyz="0 0 0" />
      <mass value="0.015" />
      <inertia ixx="5.0e-06" ixy="0.0" ixz="0.0"
               iyy="5.0e-06" iyz="0.0"
               izz="6.0e-06" />
    </inertial>
  </link>

  <joint name="right_range_joint" type="fixed">
    <parent link="base_link"/>
    <child link="right_range_link"/>
    <origin xyz="0.020 -0.090 0.055" rpy="0 0 -1.5708"/>
  </joint>

  <link name="right_range_link">
    <visual>
      <origin xyz="0 0 0" rpy="0 0 0"/>
      <geometry>
        <box size="0.026 0.018 0.020"/>
      </geometry>
      <material name="sensor_glass"/>
    </visual>

    <collision>
      <origin xyz="0 0 0" rpy="0 0 0"/>
      <geometry>
        <box size="0.026 0.018 0.020"/>
      </geometry>
    </collision>

    <inertial>
      <origin xyz="0 0 0" />
      <mass value="0.015" />
      <inertia ixx="5.0e-06" ixy="0.0" ixz="0.0"
               iyy="5.0e-06" iyz="0.0"
               izz="6.0e-06" />
    </inertial>
  </link>

  <joint name="top_payload_deck_joint" type="fixed">
    <parent link="base_link"/>
    <child link="top_payload_deck_link"/>
    <origin xyz="-0.015 0 0.088" rpy="0 0 0"/>
  </joint>

  <link name="top_payload_deck_link">
    <visual>
      <origin xyz="0 0 0" rpy="0 0 0"/>
      <geometry>
        <box size="0.165 0.135 0.010"/>
      </geometry>
      <material name="matte_black"/>
    </visual>

    <collision>
      <origin xyz="0 0 0" rpy="0 0 0"/>
      <geometry>
        <box size="0.165 0.135 0.010"/>
      </geometry>
    </collision>

    <inertial>
      <origin xyz="0 0 0" />
      <mass value="0.055" />
      <inertia ixx="2.0e-05" ixy="0.0" ixz="0.0"
               iyy="2.2e-05" iyz="0.0"
               izz="3.0e-05" />
    </inertial>
  </link>

  <joint name="front_yellow_trim_joint" type="fixed">
    <parent link="base_link"/>
    <child link="front_yellow_trim_link"/>
    <origin xyz="0.077 0 0.061" rpy="0 0 0"/>
  </joint>

  <link name="front_yellow_trim_link">
    <visual>
      <origin xyz="0 0 0" rpy="0 0 0"/>
      <geometry>
        <box size="0.010 0.145 0.012"/>
      </geometry>
      <material name="safety_yellow"/>
    </visual>

    <collision>
      <origin xyz="0 0 0" rpy="0 0 0"/>
      <geometry>
        <box size="0.010 0.145 0.012"/>
      </geometry>
    </collision>

    <inertial>
      <origin xyz="0 0 0" />
      <mass value="0.008" />
      <inertia ixx="2.0e-06" ixy="0.0" ixz="0.0"
               iyy="2.0e-06" iyz="0.0"
               izz="3.0e-06" />
    </inertial>
  </link>

  <joint name="left_yellow_trim_joint" type="fixed">
    <parent link="base_link"/>
    <child link="left_yellow_trim_link"/>
    <origin xyz="-0.015 0.085 0.061" rpy="0 0 0"/>
  </joint>

  <link name="left_yellow_trim_link">
    <visual>
      <origin xyz="0 0 0" rpy="0 0 0"/>
      <geometry>
        <box size="0.140 0.008 0.012"/>
      </geometry>
      <material name="safety_yellow"/>
    </visual>

    <collision>
      <origin xyz="0 0 0" rpy="0 0 0"/>
      <geometry>
        <box size="0.140 0.008 0.012"/>
      </geometry>
    </collision>

    <inertial>
      <origin xyz="0 0 0" />
      <mass value="0.008" />
      <inertia ixx="2.0e-06" ixy="0.0" ixz="0.0"
               iyy="2.0e-06" iyz="0.0"
               izz="3.0e-06" />
    </inertial>
  </link>

  <joint name="right_yellow_trim_joint" type="fixed">
    <parent link="base_link"/>
    <child link="right_yellow_trim_link"/>
    <origin xyz="-0.015 -0.085 0.061" rpy="0 0 0"/>
  </joint>

  <link name="right_yellow_trim_link">
    <visual>
      <origin xyz="0 0 0" rpy="0 0 0"/>
      <geometry>
        <box size="0.140 0.008 0.012"/>
      </geometry>
      <material name="safety_yellow"/>
    </visual>

    <collision>
      <origin xyz="0 0 0" rpy="0 0 0"/>
      <geometry>
        <box size="0.140 0.008 0.012"/>
      </geometry>
    </collision>

    <inertial>
      <origin xyz="0 0 0" />
      <mass value="0.008" />
      <inertia ixx="2.0e-06" ixy="0.0" ixz="0.0"
               iyy="2.0e-06" iyz="0.0"
               izz="3.0e-06" />
    </inertial>
  </link>

  <joint name="sensor_bridge_left_post_joint" type="fixed">
    <parent link="base_link"/>
    <child link="sensor_bridge_left_post_link"/>
    <origin xyz="0.035 0.048 0.107" rpy="0 0 0"/>
  </joint>

  <link name="sensor_bridge_left_post_link">
    <visual>
      <origin xyz="0 0 0" rpy="0 0 0"/>
      <geometry>
        <box size="0.010 0.010 0.052"/>
      </geometry>
      <material name="matte_black"/>
    </visual>
    <collision>
      <origin xyz="0 0 0" rpy="0 0 0"/>
      <geometry>
        <box size="0.010 0.010 0.052"/>
      </geometry>
    </collision>
    <inertial>
      <origin xyz="0 0 0" />
      <mass value="0.012" />
      <inertia ixx="5.0e-06" ixy="0.0" ixz="0.0"
               iyy="5.0e-06" iyz="0.0"
               izz="5.0e-06" />
    </inertial>
  </link>

  <joint name="sensor_bridge_right_post_joint" type="fixed">
    <parent link="base_link"/>
    <child link="sensor_bridge_right_post_link"/>
    <origin xyz="0.035 -0.048 0.107" rpy="0 0 0"/>
  </joint>

  <link name="sensor_bridge_right_post_link">
    <visual>
      <origin xyz="0 0 0" rpy="0 0 0"/>
      <geometry>
        <box size="0.010 0.010 0.052"/>
      </geometry>
      <material name="matte_black"/>
    </visual>
    <collision>
      <origin xyz="0 0 0" rpy="0 0 0"/>
      <geometry>
        <box size="0.010 0.010 0.052"/>
      </geometry>
    </collision>
    <inertial>
      <origin xyz="0 0 0" />
      <mass value="0.012" />
      <inertia ixx="5.0e-06" ixy="0.0" ixz="0.0"
               iyy="5.0e-06" iyz="0.0"
               izz="5.0e-06" />
    </inertial>
  </link>

  <joint name="sensor_bridge_crossbar_joint" type="fixed">
    <parent link="base_link"/>
    <child link="sensor_bridge_crossbar_link"/>
    <origin xyz="0.035 0 0.128" rpy="0 0 0"/>
  </joint>

  <link name="sensor_bridge_crossbar_link">
    <visual>
      <origin xyz="0 0 0" rpy="0 0 0"/>
      <geometry>
        <box size="0.070 0.112 0.010"/>
      </geometry>
      <material name="matte_black"/>
    </visual>
    <collision>
      <origin xyz="0 0 0" rpy="0 0 0"/>
      <geometry>
        <box size="0.070 0.112 0.010"/>
      </geometry>
    </collision>
    <inertial>
      <origin xyz="0 0 0" />
      <mass value="0.020" />
      <inertia ixx="7.0e-06" ixy="0.0" ixz="0.0"
               iyy="7.0e-06" iyz="0.0"
               izz="9.0e-06" />
    </inertial>
  </link>

  <joint name="front_sensor_bezel_joint" type="fixed">
    <parent link="base_link"/>
    <child link="front_sensor_bezel_link"/>
    <origin xyz="0.121 0 0.045" rpy="0 0 0"/>
  </joint>

  <link name="front_sensor_bezel_link">
    <visual>
      <origin xyz="0 0 0" rpy="0 0 0"/>
      <geometry>
        <box size="0.004 0.048 0.018"/>
      </geometry>
      <material name="sensor_glass"/>
    </visual>
    <collision>
      <origin xyz="0 0 0" rpy="0 0 0"/>
      <geometry>
        <box size="0.004 0.048 0.018"/>
      </geometry>
    </collision>
    <inertial>
      <origin xyz="0 0 0" />
      <mass value="0.006" />
      <inertia ixx="1.0e-06" ixy="0.0" ixz="0.0"
               iyy="1.0e-06" iyz="0.0"
               izz="1.0e-06" />
    </inertial>
  </link>

  <joint name="left_sensor_bezel_joint" type="fixed">
    <parent link="base_link"/>
    <child link="left_sensor_bezel_link"/>
    <origin xyz="0.020 0.101 0.055" rpy="0 0 0"/>
  </joint>

  <link name="left_sensor_bezel_link">
    <visual>
      <origin xyz="0 0 0" rpy="0 0 0"/>
      <geometry>
        <box size="0.030 0.004 0.020"/>
      </geometry>
      <material name="sensor_glass"/>
    </visual>
    <collision>
      <origin xyz="0 0 0" rpy="0 0 0"/>
      <geometry>
        <box size="0.030 0.004 0.020"/>
      </geometry>
    </collision>
    <inertial>
      <origin xyz="0 0 0" />
      <mass value="0.006" />
      <inertia ixx="1.0e-06" ixy="0.0" ixz="0.0"
               iyy="1.0e-06" iyz="0.0"
               izz="1.0e-06" />
    </inertial>
  </link>

  <joint name="right_sensor_bezel_joint" type="fixed">
    <parent link="base_link"/>
    <child link="right_sensor_bezel_link"/>
    <origin xyz="0.020 -0.101 0.055" rpy="0 0 0"/>
  </joint>

  <link name="right_sensor_bezel_link">
    <visual>
      <origin xyz="0 0 0" rpy="0 0 0"/>
      <geometry>
        <box size="0.030 0.004 0.020"/>
      </geometry>
      <material name="sensor_glass"/>
    </visual>
    <collision>
      <origin xyz="0 0 0" rpy="0 0 0"/>
      <geometry>
        <box size="0.030 0.004 0.020"/>
      </geometry>
    </collision>
    <inertial>
      <origin xyz="0 0 0" />
      <mass value="0.006" />
      <inertia ixx="1.0e-06" ixy="0.0" ixz="0.0"
               iyy="1.0e-06" iyz="0.0"
               izz="1.0e-06" />
    </inertial>
  </link>

  <joint name="deck_fastener_fl_joint" type="fixed">
    <parent link="base_link"/>
    <child link="deck_fastener_fl_link"/>
    <origin xyz="0.045 0.048 0.095" rpy="0 0 0"/>
  </joint>

  <link name="deck_fastener_fl_link">
    <visual>
      <origin xyz="0 0 0" rpy="0 0 0"/>
      <geometry>
        <cylinder length="0.003" radius="0.005"/>
      </geometry>
      <material name="grey"/>
    </visual>
    <inertial>
      <origin xyz="0 0 0" />
      <mass value="0.002" />
      <inertia ixx="1.0e-07" ixy="0.0" ixz="0.0"
               iyy="1.0e-07" iyz="0.0"
               izz="1.0e-07" />
    </inertial>
  </link>

  <joint name="deck_fastener_fr_joint" type="fixed">
    <parent link="base_link"/>
    <child link="deck_fastener_fr_link"/>
    <origin xyz="0.045 -0.048 0.095" rpy="0 0 0"/>
  </joint>

  <link name="deck_fastener_fr_link">
    <visual>
      <origin xyz="0 0 0" rpy="0 0 0"/>
      <geometry>
        <cylinder length="0.003" radius="0.005"/>
      </geometry>
      <material name="grey"/>
    </visual>
    <inertial>
      <origin xyz="0 0 0" />
      <mass value="0.002" />
      <inertia ixx="1.0e-07" ixy="0.0" ixz="0.0"
               iyy="1.0e-07" iyz="0.0"
               izz="1.0e-07" />
    </inertial>
  </link>

  <joint name="deck_fastener_rl_joint" type="fixed">
    <parent link="base_link"/>
    <child link="deck_fastener_rl_link"/>
    <origin xyz="-0.075 0.048 0.095" rpy="0 0 0"/>
  </joint>

  <link name="deck_fastener_rl_link">
    <visual>
      <origin xyz="0 0 0" rpy="0 0 0"/>
      <geometry>
        <cylinder length="0.003" radius="0.005"/>
      </geometry>
      <material name="grey"/>
    </visual>
    <inertial>
      <origin xyz="0 0 0" />
      <mass value="0.002" />
      <inertia ixx="1.0e-07" ixy="0.0" ixz="0.0"
               iyy="1.0e-07" iyz="0.0"
               izz="1.0e-07" />
    </inertial>
  </link>

  <joint name="deck_fastener_rr_joint" type="fixed">
    <parent link="base_link"/>
    <child link="deck_fastener_rr_link"/>
    <origin xyz="-0.075 -0.048 0.095" rpy="0 0 0"/>
  </joint>

  <link name="deck_fastener_rr_link">
    <visual>
      <origin xyz="0 0 0" rpy="0 0 0"/>
      <geometry>
        <cylinder length="0.003" radius="0.005"/>
      </geometry>
      <material name="grey"/>
    </visual>
    <inertial>
      <origin xyz="0 0 0" />
      <mass value="0.002" />
      <inertia ixx="1.0e-07" ixy="0.0" ixz="0.0"
               iyy="1.0e-07" iyz="0.0"
               izz="1.0e-07" />
    </inertial>
  </link>

  <joint name="wheel_left_front_joint" type="continuous">
    <parent link="base_link"/>
    <child link="wheel_left_front_link"/>
    <origin xyz="0.060 0.078 0.023" rpy="-1.57 0 0"/>
    <axis xyz="0 0 1"/>
  </joint>

  <link name="wheel_left_front_link">
    <visual>
      <origin xyz="0 0 0" rpy="1.57 0 0"/>
      <geometry>
        <mesh filename="package://turtlebot3_description/meshes/wheels/left_tire.stl" scale="0.001 0.001 0.001"/>
      </geometry>
      <material name="dark"/>
    </visual>

    <collision>
      <origin xyz="0 0 0" rpy="0 0 0"/>
      <geometry>
        <cylinder length="0.018" radius="0.033"/>
      </geometry>
    </collision>

    <inertial>
      <origin xyz="0 0 0" />
      <mass value="2.8498940e-02" />
      <inertia ixx="1.1175580e-05" ixy="0.0" ixz="0.0"
               iyy="1.1192413e-05" iyz="0.0"
               izz="2.0712558e-05" />
    </inertial>
  </link>

  <joint name="wheel_right_front_joint" type="continuous">
    <parent link="base_link"/>
    <child link="wheel_right_front_link"/>
    <origin xyz="0.060 -0.078 0.023" rpy="-1.57 0 0"/>
    <axis xyz="0 0 1"/>
  </joint>

  <link name="wheel_right_front_link">
    <visual>
      <origin xyz="0 0 0" rpy="1.57 0 0"/>
      <geometry>
        <mesh filename="package://turtlebot3_description/meshes/wheels/right_tire.stl" scale="0.001 0.001 0.001"/>
      </geometry>
      <material name="dark"/>
    </visual>

    <collision>
      <origin xyz="0 0 0" rpy="0 0 0"/>
      <geometry>
        <cylinder length="0.018" radius="0.033"/>
      </geometry>
    </collision>

    <inertial>
      <origin xyz="0 0 0" />
      <mass value="2.8498940e-02" />
      <inertia ixx="1.1175580e-05" ixy="0.0" ixz="0.0"
               iyy="1.1192413e-05" iyz="0.0"
               izz="2.0712558e-05" />
    </inertial>
  </link>

  <joint name="wheel_left_rear_joint" type="continuous">
    <parent link="base_link"/>
    <child link="wheel_left_rear_link"/>
    <origin xyz="-0.060 0.078 0.023" rpy="-1.57 0 0"/>
    <axis xyz="0 0 1"/>
  </joint>

  <link name="wheel_left_rear_link">
    <visual>
      <origin xyz="0 0 0" rpy="1.57 0 0"/>
      <geometry>
        <mesh filename="package://turtlebot3_description/meshes/wheels/left_tire.stl" scale="0.001 0.001 0.001"/>
      </geometry>
      <material name="dark"/>
    </visual>

    <collision>
      <origin xyz="0 0 0" rpy="0 0 0"/>
      <geometry>
        <cylinder length="0.018" radius="0.033"/>
      </geometry>
    </collision>

    <inertial>
      <origin xyz="0 0 0" />
      <mass value="2.8498940e-02" />
      <inertia ixx="1.1175580e-05" ixy="0.0" ixz="0.0"
               iyy="1.1192413e-05" iyz="0.0"
               izz="2.0712558e-05" />
    </inertial>
  </link>

  <joint name="wheel_right_rear_joint" type="continuous">
    <parent link="base_link"/>
    <child link="wheel_right_rear_link"/>
    <origin xyz="-0.060 -0.078 0.023" rpy="-1.57 0 0"/>
    <axis xyz="0 0 1"/>
  </joint>

  <link name="wheel_right_rear_link">
    <visual>
      <origin xyz="0 0 0" rpy="1.57 0 0"/>
      <geometry>
        <mesh filename="package://turtlebot3_description/meshes/wheels/right_tire.stl" scale="0.001 0.001 0.001"/>
      </geometry>
      <material name="dark"/>
    </visual>

    <collision>
      <origin xyz="0 0 0" rpy="0 0 0"/>
      <geometry>
        <cylinder length="0.018" radius="0.033"/>
      </geometry>
    </collision>

    <inertial>
      <origin xyz="0 0 0" />
      <mass value="2.8498940e-02" />
      <inertia ixx="1.1175580e-05" ixy="0.0" ixz="0.0"
               iyy="1.1192413e-05" iyz="0.0"
               izz="2.0712558e-05" />
    </inertial>
  </link>

  <joint name="imu_joint" type="fixed">
    <parent link="base_link"/>
    <child link="imu_link"/>
    <origin xyz="-0.020 0 0.060" rpy="0 0 0"/>
  </joint>

  <link name="imu_link"/>

  <joint name="scan_joint" type="fixed">
    <parent link="base_link"/>
    <child link="base_scan"/>
    <origin xyz="0.035 0 0.085" rpy="0 0 0"/>
  </joint>

  <link name="base_scan">
    <visual>
      <origin xyz="0 0 0.0" rpy="0 0 0"/>
      <geometry>
        <mesh filename="package://turtlebot3_description/meshes/sensors/lds.stl" scale="0.001 0.001 0.001"/>
      </geometry>
      <material name="dark"/>
    </visual>

    <collision>
      <origin xyz="0.015 0 -0.0065" rpy="0 0 0"/>
      <geometry>
        <cylinder length="0.0315" radius="0.055"/>
      </geometry>
    </collision>

    <inertial>
      <mass value="0.114" />
      <origin xyz="0 0 0" />
      <inertia ixx="0.001" ixy="0.0" ixz="0.0"
               iyy="0.001" iyz="0.0"
               izz="0.001" />
    </inertial>
  </link>
</robot>
